Workbook
Name IQ_CH: 110000
Name IQ_CQ: 5000
Name IQ_CY: 10000
Name IQ_DAILY: 500000
Name IQ_FH: 100000
Name IQ_FQ: 500
Name IQ_FY: 1000
Name IQ_LTM: 2000
Name IQ_MONTH: 15000
Name IQ_NTM: 6000
Name IQ_WEEK: 50000
Name IQ_YTD: 3000
Name UPDATE: 'Data Sheet'!$E$1

Sheet HistoricalFS
B2: ="Historical Financial Statement - "&'Data Sheet'!B1 -> Historical Financial Statement - ASIAN PAINTS LTD
B3: Years | C3: ='Data Sheet'!B16 -> 42825 | D3: ='Data Sheet'!C16 -> 43190 | E3: ='Data Sheet'!D16 -> 43555 | F3: ='Data Sheet'!E16 -> 43921 | G3: ='Data Sheet'!F16 -> 44286 | H3: ='Data Sheet'!G16 -> 44651 | I3: ='Data Sheet'!H16 -> 45016 | J3: ='Data Sheet'!I16 -> 45382 | ... L3: ='Data Sheet'!K16 -> 46112 | M3: LTM
A5: # | B5: Income Statement
B6: Sales | C6: =IFERROR('Data Sheet'!B17,0) -> 15061.99 | D6: =IFERROR('Data Sheet'!C17,0) -> 16824.55 | E6: =IFERROR('Data Sheet'!D17,0) -> 19240.13 | F6: =IFERROR('Data Sheet'!E17,0) -> 20211.25 | G6: =IFERROR('Data Sheet'!F17,0) -> 21712.79 | H6: =IFERROR('Data Sheet'!G17,0) -> 29101.28 | I6: =IFERROR('Data Sheet'!H17,0) -> 34488.59 | J6: =IFERROR('Data Sheet'!I17,0) -> 35494.73 | ... L6: =IFERROR('Data Sheet'!K17,0) -> 35583.54 | M6: =IFERROR(SUM('Data Sheet'!H42:K42),0) -> 37186.93
B7: Sales Growth | C7: - | D7: =D6/C6-1 -> 0.11702039 | E7: =E6/D6-1 -> 0.14357472 | F7: =F6/E6-1 -> 0.050473671 | G7: =G6/F6-1 -> 0.074292288 | H7: =H6/G6-1 -> 0.34028285 | I7: =I6/H6-1 -> 0.18512278 | J7: =J6/I6-1 -> 0.029173127 | K7: =K6/J6-1 -> -0.044770308 | ... M7: =M6/L6-1 -> 0.045059879
B9: COGS | C9: =IFERROR(SUM('Data Sheet'!B18,'Data Sheet'!B20:B22)-1*'Data Sheet'!B19,0) -> 9732.66 | D9: =IFERROR(SUM('Data Sheet'!C18,'Data Sheet'!C20:C22)-1*'Data Sheet'!C19,0) -> 11194.17 | E9: =IFERROR(SUM('Data Sheet'!D18,'Data Sheet'!D20:D22)-1*'Data Sheet'!D19,0) -> 12905.81 | F9: =IFERROR(SUM('Data Sheet'!E18,'Data Sheet'!E20:E22)-1*'Data Sheet'!E19,0) -> 13158.02 | G9: =IFERROR(SUM('Data Sheet'!F18,'Data Sheet'!F20:F22)-1*'Data Sheet'!F19,0) -> 14035.07 | H9: =IFERROR(SUM('Data Sheet'!G18,'Data Sheet'!G20:G22)-1*'Data Sheet'!G19,0) -> 20590.57 | I9: =IFERROR(SUM('Data Sheet'!H18,'Data Sheet'!H20:H22)-1*'Data Sheet'!H19,0) -> 23766.7 | J9: =IFERROR(SUM('Data Sheet'!I18,'Data Sheet'!I20:I22)-1*'Data Sheet'!I19,0) -> 23009.99 | ... L9: =IFERROR(SUM('Data Sheet'!K18,'Data Sheet'!K20:K22)-1*'Data Sheet'!K19,0) -> 23489.63 | M9: =IFERROR(SUM('Data Sheet'!H43:K43),0) -> 29947.22
B10: COGS % Sales | C10: =C9/C6 -> 0.64617358 | D10: =D9/D6 -> 0.66534736 | E10: =E9/E6 -> 0.67077561 | F10: =F9/F6 -> 0.65102455 | G10: =G9/G6 -> 0.64639643 | H10: =H9/H6 -> 0.7075486 | I10: =I9/I6 -> 0.68911776 | J10: =J9/J6 -> 0.64826497 | ... M10: =M9/M6 -> 0.80531574
B12: Gross Profit | C12: =C6-C9 -> 5329.33 | D12: =D6-D9 -> 5630.38 | E12: =E6-E9 -> 6334.32 | F12: =F6-F9 -> 7053.23 | G12: =G6-G9 -> 7677.72 | H12: =H6-H9 -> 8510.71 | I12: =I6-I9 -> 10721.89 | J12: =J6-J9 -> 12484.74 | ... M12: =M6-M9 -> 7239.71
B13: Gross Margins | C13: =C12/C6 -> 0.35382642 | D13: =D12/D6 -> 0.33465264 | E13: =E12/E6 -> 0.32922439 | F13: =F12/F6 -> 0.34897545 | G13: =G12/G6 -> 0.35360357 | H13: =H12/H6 -> 0.2924514 | I13: =I12/I6 -> 0.31088224 | J13: =J12/J6 -> 0.35173503 | ... M13: =M12/M6 -> 0.19468426
B15: Selling & General Expenses | C15: =IFERROR(SUM('Data Sheet'!B23:B24),0) -> 2335.57 | D15: =IFERROR(SUM('Data Sheet'!C23:C24),0) -> 2426.37 | E15: =IFERROR(SUM('Data Sheet'!D23:D24),0) -> 2569.38 | F15: =IFERROR(SUM('Data Sheet'!E23:E24),0) -> 2891.46 | G15: =IFERROR(SUM('Data Sheet'!F23:F24),0) -> 2822.12 | H15: =IFERROR(SUM('Data Sheet'!G23:G24),0) -> 3707.1 | I15: =IFERROR(SUM('Data Sheet'!H23:H24),0) -> 4462.05 | J15: =IFERROR(SUM('Data Sheet'!I23:I24),0) -> 4899.76 | ... L15: =IFERROR(SUM('Data Sheet'!K23:K24),0) -> 5394.18
B16: S&G Exp % Sales | C16: =C15/C6 -> 0.15506384 | D16: =D15/D6 -> 0.14421604 | E16: =E15/E6 -> 0.13354276 | F16: =F15/F6 -> 0.14306191 | G16: =G15/G6 -> 0.12997501 | H16: =H15/H6 -> 0.12738615 | I16: =I15/I6 -> 0.12937757 | J16: =J15/J6 -> 0.1380419 | ... M16: =M15/M6 -> 0
B18: EBITDA | C18: =C12-C15 -> 2993.76 | D18: =D12-D15 -> 3204.01 | E18: =E12-E15 -> 3764.94 | F18: =F12-F15 -> 4161.77 | G18: =G12-G15 -> 4855.6 | H18: =H12-H15 -> 4803.61 | I18: =I12-I15 -> 6259.84 | J18: =J12-J15 -> 7584.98 | ... L18: =L12-L15 -> 6699.73 | M18: =IFERROR(SUM('Data Sheet'!H51:K51),0) -> 7949.13
B19: EBITDA Margins | C19: =C18/C6 -> 0.19876258 | D19: =D18/D6 -> 0.19043659 | E19: =E18/E6 -> 0.19568163 | F19: =F18/F6 -> 0.20591354 | G19: =G18/G6 -> 0.22362856 | H19: =H18/H6 -> 0.16506525 | I19: =I18/I6 -> 0.18150467 | J19: =J18/J6 -> 0.21369313 | ... M19: =M18/M6 -> 0.21376139
B21: Interest | C21: =IFERROR('Data Sheet'!B27,0) -> 37.33 | D21: =IFERROR('Data Sheet'!C27,0) -> 41.47 | E21: =IFERROR('Data Sheet'!D27,0) -> 110.47 | F21: =IFERROR('Data Sheet'!E27,0) -> 102.33 | G21: =IFERROR('Data Sheet'!F27,0) -> 91.63 | H21: =IFERROR('Data Sheet'!G27,0) -> 95.41 | I21: =IFERROR('Data Sheet'!H27,0) -> 144.45 | J21: =IFERROR('Data Sheet'!I27,0) -> 205.17 | ... L21: =IFERROR('Data Sheet'!K27,0) -> 195.41 | M21: =IFERROR(SUM('Data Sheet'!H46:K46),0) -> 198.74
B22: Interest % Sales | C22: =C21/C6 -> 0.0024784242 | D22: =D21/D6 -> 0.0024648505 | E22: =E21/E6 -> 0.0057416452 | F22: =F21/F6 -> 0.0050630218 | G22: =G21/G6 -> 0.0042200933 | H22: =H21/H6 -> 0.0032785499 | I22: =I21/I6 -> 0.0041883417 | J22: =J21/J6 -> 0.0057802947 | ... M22: =M21/M6 -> 0.0053443508
B24: Depreciation | C24: =IFERROR('Data Sheet'!B26,0) -> 334.79 | D24: =IFERROR('Data Sheet'!C26,0) -> 360.47 | E24: =IFERROR('Data Sheet'!D26,0) -> 622.14 | F24: =IFERROR('Data Sheet'!E26,0) -> 780.5 | G24: =IFERROR('Data Sheet'!F26,0) -> 791.27 | H24: =IFERROR('Data Sheet'!G26,0) -> 816.36 | I24: =IFERROR('Data Sheet'!H26,0) -> 858.02 | J24: =IFERROR('Data Sheet'!I26,0) -> 853 | ... L24: =IFERROR('Data Sheet'!K26,0) -> 1228.85 | M24: =IFERROR(SUM('Data Sheet'!H45:K45),0) -> 1232.17
B25: Depreciation%Sales | C25: =C24/C6 -> 0.022227475 | D25: =D24/D6 -> 0.021425239 | E25: =E24/E6 -> 0.03233554 | F25: =F24/F6 -> 0.038617107 | G25: =G24/G6 -> 0.036442576 | H25: =H24/H6 -> 0.028052374 | I25: =I24/I6 -> 0.024878373 | J25: =J24/J6 -> 0.024031737 | ... M25: =M24/M6 -> 0.033134491
B27: EBIT | C27: =IFERROR(C18-C24,0) -> 2658.97 | D27: =IFERROR(D18-D24,0) -> 2843.54 | E27: =IFERROR(E18-E24,0) -> 3142.8 | F27: =IFERROR(F18-F24,0) -> 3381.27 | G27: =IFERROR(G18-G24,0) -> 4064.33 | H27: =IFERROR(H18-H24,0) -> 3987.25 | I27: =IFERROR(I18-I24,0) -> 5401.82 | J27: =IFERROR(J18-J24,0) -> 6731.98 | ... M27: =IFERROR(M18-M24,0) -> 6716.96
B28: EBIT Margins | C28: =C27/C6 -> 0.17653511 | D28: =D27/D6 -> 0.16901136 | E28: =E27/E6 -> 0.16334609 | F28: =F27/F6 -> 0.16729643 | G28: =G27/G6 -> 0.18718599 | H28: =H27/H6 -> 0.13701287 | I28: =I27/I6 -> 0.15662629 | J28: =J27/J6 -> 0.18966139 | ... M28: =M27/M6 -> 0.1806269
B30: Earnings Before Tax | C30: =IFERROR(C18-SUM(C24,C21),0) -> 2621.64 | D30: =IFERROR(D18-SUM(D24,D21),0) -> 2802.07 | E30: =IFERROR(E18-SUM(E24,E21),0) -> 3032.33 | F30: =IFERROR(F18-SUM(F24,F21),0) -> 3278.94 | G30: =IFERROR(G18-SUM(G24,G21),0) -> 3972.7 | H30: =IFERROR(H18-SUM(H24,H21),0) -> 3891.84 | I30: =IFERROR(I18-SUM(I24,I21),0) -> 5257.37 | J30: =IFERROR(J18-SUM(J24,J21),0) -> 6526.81 | ... M30: =IFERROR(M18-SUM(M24,M21),0) -> 6518.22
B31: EBT % Sales | C31: =C30/C6 -> 0.17405668 | D31: =D30/D6 -> 0.1665465 | E31: =E30/E6 -> 0.15760444 | F31: =F30/F6 -> 0.16223341 | G31: =G30/G6 -> 0.18296589 | H31: =H30/H6 -> 0.13373432 | I31: =I30/I6 -> 0.15243795 | J31: =J30/J6 -> 0.1838811 | ... M31: =M30/M6 -> 0.17528255
B33: Tax | C33: =IFERROR('Data Sheet'!B29,0) -> 943.29 | D33: =IFERROR('Data Sheet'!C29,0) -> 1040.96 | E33: =IFERROR('Data Sheet'!D29,0) -> 1098.06 | F33: =IFERROR('Data Sheet'!E29,0) -> 854.85 | G33: =IFERROR('Data Sheet'!F29,0) -> 1097.6 | H33: =IFERROR('Data Sheet'!G29,0) -> 1102.91 | I33: =IFERROR('Data Sheet'!H29,0) -> 1493.5 | J33: =IFERROR('Data Sheet'!I29,0) -> 1790.08 | ... L33: =IFERROR('Data Sheet'!K29,0) -> 1608.75 | M33: =IFERROR(SUM('Data Sheet'!H48:K48),0) -> 1753.39
B34: Effective Tax Rate | C34: =C33/C30 -> 0.35980913 | D34: =D33/D30 -> 0.37149679 | E34: =E33/E30 -> 0.36211758 | F34: =F33/F30 -> 0.26070925 | G34: =G33/G30 -> 0.27628565 | H34: =H33/H30 -> 0.28339038 | I34: =I33/I30 -> 0.2840774 | J34: =J33/J30 -> 0.27426568 | ... M34: =M33/M30 -> 0.26899828
B36: Net Profit | C36: =IFERROR(C30-C33,0) -> 1678.35 | D36: =IFERROR(D30-D33,0) -> 1761.11 | E36: =IFERROR(E30-E33,0) -> 1934.27 | F36: =IFERROR(F30-F33,0) -> 2424.09 | G36: =IFERROR(G30-G33,0) -> 2875.1 | H36: =IFERROR(H30-H33,0) -> 2788.93 | I36: =IFERROR(I30-I33,0) -> 3763.87 | J36: =IFERROR(J30-J33,0) -> 4736.73 | ... M36: =IFERROR(M30-M33,0) -> 4764.83
B37: Net Margins | C37: =C36/C6 -> 0.1114295 | D37: =D36/D6 -> 0.10467501 | E37: =E36/E6 -> 0.1005331 | F37: =F36/F6 -> 0.11993766 | G37: =G36/G6 -> 0.13241504 | H37: =H36/H6 -> 0.095835303 | I37: =I36/I6 -> 0.10913377 | J37: =J36/J6 -> 0.13344882 | ... M37: =M36/M6 -> 0.12813185
B39: No of Equity Shares | C39: =IFERROR('Data Sheet'!B93,0) -> 95.92 | D39: =IFERROR('Data Sheet'!C93,0) -> 95.92 | E39: =IFERROR('Data Sheet'!D93,0) -> 95.92 | F39: =IFERROR('Data Sheet'!E93,0) -> 95.92 | G39: =IFERROR('Data Sheet'!F93,0) -> 95.92 | H39: =IFERROR('Data Sheet'!G93,0) -> 95.92 | I39: =IFERROR('Data Sheet'!H93,0) -> 95.92 | J39: =IFERROR('Data Sheet'!I93,0) -> 95.92 | ... L39: =IFERROR('Data Sheet'!K93,0) -> 95.92 | M39: =L39 -> 95.92
B41: Earnings per Share | C41: =IFERROR(C36/C39,0) -> 17.497394 | D41: =IFERROR(D36/D39,0) -> 18.360196 | E41: =IFERROR(E36/E39,0) -> 20.16545 | F41: =IFERROR(F36/F39,0) -> 25.271997 | G41: =IFERROR(G36/G39,0) -> 29.973937 | H41: =IFERROR(H36/H39,0) -> 29.075584 | I41: =IFERROR(I36/I39,0) -> 39.239679 | J41: =IFERROR(J36/J39,0) -> 49.382089 | ... M41: =IFERROR(M36/M39,0) -> 49.675042
B42: EPS Growth % | D42: =IFERROR(D41/C41-1,0) -> 0.049310335 | E42: =IFERROR(E41/D41-1,0) -> 0.098324352 | F42: =IFERROR(F41/E41-1,0) -> 0.25323249 | G42: =IFERROR(G41/F41-1,0) -> 0.18605332 | H42: =IFERROR(H41/G41-1,0) -> -0.029971131 | I42: =IFERROR(I41/H41-1,0) -> 0.34957493 | J42: =IFERROR(J41/I41-1,0) -> 0.25847333 | K42: =IFERROR(K41/J41-1,0) -> -0.29075755 | ... M42: =IFERROR(M41/L41-1,0) -> 0.29948019
B44: Dividend per Share | C44: =IFERROR('Data Sheet'!B31/HistoricalFS!C39,0) -> 10.300042 | D44: =IFERROR('Data Sheet'!C31/HistoricalFS!D39,0) -> 8.6999583 | E44: =IFERROR('Data Sheet'!D31/HistoricalFS!E39,0) -> 10.5 | F44: =IFERROR('Data Sheet'!E31/HistoricalFS!F39,0) -> 12 | G44: =IFERROR('Data Sheet'!F31/HistoricalFS!G39,0) -> 17.849979 | H44: =IFERROR('Data Sheet'!G31/HistoricalFS!H39,0) -> 19.150021 | I44: =IFERROR('Data Sheet'!H31/HistoricalFS!I39,0) -> 25.650021 | J44: =IFERROR('Data Sheet'!I31/HistoricalFS!J39,0) -> 33.300042 | ... M44: =IFERROR('Data Sheet'!L31/HistoricalFS!M39,0) -> 0
B45: Dividend payout ratio | C45: =IFERROR(C44/C41,0) -> 0.58866148 | D45: =IFERROR(D44/D41,0) -> 0.47384888 | E45: =IFERROR(E44/E41,0) -> 0.52069256 | F45: =IFERROR(F44/F41,0) -> 0.47483386 | G45: =IFERROR(G44/G41,0) -> 0.59551668 | H45: =IFERROR(H44/H41,0) -> 0.65862894 | I45: =IFERROR(I44/I41,0) -> 0.65367561 | J45: =IFERROR(J44/J41,0) -> 0.6743344 | ... M45: =IFERROR(M44/M41,0) -> 0
B47: Retained Earnings | C47: =IFERROR(IF(C41>C44,1-C45,0),0) -> 0.41133852 | D47: =IFERROR(IF(D41>D44,1-D45,0),0) -> 0.52615112 | E47: =IFERROR(IF(E41>E44,1-E45,0),0) -> 0.47930744 | F47: =IFERROR(IF(F41>F44,1-F45,0),0) -> 0.52516614 | G47: =IFERROR(IF(G41>G44,1-G45,0),0) -> 0.40448332 | H47: =IFERROR(IF(H41>H44,1-H45,0),0) -> 0.34137106 | I47: =IFERROR(IF(I41>I44,1-I45,0),0) -> 0.34632439 | J47: =IFERROR(IF(J41>J44,1-J45,0),0) -> 0.3256656 | ... M47: =IFERROR(IF(M41>M44,1-M45,0),0) -> 1
A49: # | B49: Balance Sheet
B50: Equity Share Capital | C50: =IFERROR('Data Sheet'!B57,0) -> 95.92 | D50: =IFERROR('Data Sheet'!C57,0) -> 95.92 | E50: =IFERROR('Data Sheet'!D57,0) -> 95.92 | F50: =IFERROR('Data Sheet'!E57,0) -> 95.92 | G50: =IFERROR('Data Sheet'!F57,0) -> 95.92 | H50: =IFERROR('Data Sheet'!G57,0) -> 95.92 | I50: =IFERROR('Data Sheet'!H57,0) -> 95.92 | J50: =IFERROR('Data Sheet'!I57,0) -> 95.92 | ... L50: =IFERROR('Data Sheet'!K57,0) -> 95.92
B51: Reserves | C51: =IFERROR('Data Sheet'!B58,0) -> 7507.97 | D51: =IFERROR('Data Sheet'!C58,0) -> 8314.31 | E51: =IFERROR('Data Sheet'!D58,0) -> 9374.63 | F51: =IFERROR('Data Sheet'!E58,0) -> 10034.24 | G51: =IFERROR('Data Sheet'!F58,0) -> 12710.37 | H51: =IFERROR('Data Sheet'!G58,0) -> 13715.64 | I51: =IFERROR('Data Sheet'!H58,0) -> 15896.31 | J51: =IFERROR('Data Sheet'!I58,0) -> 18632.38 | ... L51: =IFERROR('Data Sheet'!K58,0) -> 21275.67
B52: Borrowings | C52: =IFERROR('Data Sheet'!B59,0) -> 560.34 | D52: =IFERROR('Data Sheet'!C59,0) -> 533.43 | E52: =IFERROR('Data Sheet'!D59,0) -> 1319.6 | F52: =IFERROR('Data Sheet'!E59,0) -> 1118.5 | G52: =IFERROR('Data Sheet'!F59,0) -> 1093.12 | H52: =IFERROR('Data Sheet'!G59,0) -> 1586.88 | I52: =IFERROR('Data Sheet'!H59,0) -> 1932.62 | J52: =IFERROR('Data Sheet'!I59,0) -> 2474.38 | ... L52: =IFERROR('Data Sheet'!K59,0) -> 3928.93
B53: Other Liabilities | C53: =IFERROR('Data Sheet'!B60,0) -> 4240.96 | D53: =IFERROR('Data Sheet'!C60,0) -> 4819.82 | E53: =IFERROR('Data Sheet'!D60,0) -> 5458.69 | F53: =IFERROR('Data Sheet'!E60,0) -> 4889.31 | G53: =IFERROR('Data Sheet'!F60,0) -> 6455.93 | H53: =IFERROR('Data Sheet'!G60,0) -> 7559.99 | I53: =IFERROR('Data Sheet'!H60,0) -> 7854.48 | J53: =IFERROR('Data Sheet'!I60,0) -> 8698.09 | ... L53: =IFERROR('Data Sheet'!K60,0) -> 9218.23
B54: Total Liabilities | C54: =IFERROR('Data Sheet'!B61,0) -> 12405.19 | D54: =IFERROR('Data Sheet'!C61,0) -> 13763.48 | E54: =IFERROR('Data Sheet'!D61,0) -> 16248.84 | F54: =IFERROR('Data Sheet'!E61,0) -> 16137.97 | G54: =IFERROR('Data Sheet'!F61,0) -> 20355.34 | H54: =IFERROR('Data Sheet'!G61,0) -> 22958.43 | I54: =IFERROR('Data Sheet'!H61,0) -> 25779.33 | J54: =IFERROR('Data Sheet'!I61,0) -> 29900.77 | ... L54: =IFERROR('Data Sheet'!K61,0) -> 34518.75
B56: Fixed Assets Net Block | C56: =IFERROR('Data Sheet'!B62,0) -> 3303.74 | D56: =IFERROR('Data Sheet'!C62,0) -> 3732.24 | E56: =IFERROR('Data Sheet'!D62,0) -> 6496.56 | F56: =IFERROR('Data Sheet'!E62,0) -> 6272.31 | G56: =IFERROR('Data Sheet'!F62,0) -> 5858.52 | H56: =IFERROR('Data Sheet'!G62,0) -> 5519.06 | I56: =IFERROR('Data Sheet'!H62,0) -> 5770.46 | J56: =IFERROR('Data Sheet'!I62,0) -> 7146.62 | ... L56: =IFERROR('Data Sheet'!K62,0) -> 9640.28
B57: Capital Work in Progress | C57: =IFERROR('Data Sheet'!B63,0) -> 257.54 | D57: =IFERROR('Data Sheet'!C63,0) -> 1405.11 | E57: =IFERROR('Data Sheet'!D63,0) -> 209.67 | F57: =IFERROR('Data Sheet'!E63,0) -> 140.24 | G57: =IFERROR('Data Sheet'!F63,0) -> 182.98 | H57: =IFERROR('Data Sheet'!G63,0) -> 426.43 | I57: =IFERROR('Data Sheet'!H63,0) -> 1019.59 | J57: =IFERROR('Data Sheet'!I63,0) -> 2698.37 | ... L57: =IFERROR('Data Sheet'!K63,0) -> 1848.67
B58: Investments | C58: =IFERROR('Data Sheet'!B64,0) -> 2651.99 | D58: =IFERROR('Data Sheet'!C64,0) -> 2140.7 | E58: =IFERROR('Data Sheet'!D64,0) -> 2568.58 | F58: =IFERROR('Data Sheet'!E64,0) -> 2018.85 | G58: =IFERROR('Data Sheet'!F64,0) -> 4736.8 | H58: =IFERROR('Data Sheet'!G64,0) -> 3247.53 | I58: =IFERROR('Data Sheet'!H64,0) -> 4261.71 | J58: =IFERROR('Data Sheet'!I64,0) -> 4587.92 | ... L58: =IFERROR('Data Sheet'!K64,0) -> 7061.74
...

Sheet DCF
B2: Calculation of PV of FCFF | C2: ='Intrisic Growth'!K2 -> 46082 | D2: =C2+366 -> 46448 | E2: =D2+366 -> 46814 | F2: =E2+366 -> 47180 | G2: =F2+366 -> 47546 | H2: =G2+366 -> 47912
B4: EBIT | C4: ='Data Sheet'!K34-'Data Sheet'!K26 -> 6129.51 | D4: =C4*(1+$C$13) -> 7572.6715 | E4: =D4*(1+$C$13) -> 9355.618 | F4: =E4*(1+$C$13) -> 11558.35 | G4: =F4*(1+$C$13) -> 14279.704 | H4: =G4*(1+$C$13) -> 17641.787
B5: Tax Rate | C5: 0.25 | D5: =C5 -> 0.25 | E5: =D5 -> 0.25 | F5: =E5 -> 0.25 | G5: =F5 -> 0.25 | H5: =G5 -> 0.25
B6: EBIT (1-T) | C6: =C4*(1-C5) -> 4597.1325 | D6: =D4*(1-D5) -> 5679.5037 | E6: =E4*(1-E5) -> 7016.7135 | F6: =F4*(1-F5) -> 8668.7626 | G6: =G4*(1-G5) -> 10709.778 | H6: =H4*(1-H5) -> 13231.34
B7: Less Reinvestment Rate | C7: ='Intrisic Growth'!K52 -> 0.45540424 | D7: =C7 -> 0.45540424 | E7: =D7 -> 0.45540424 | F7: =E7 -> 0.45540424 | G7: =F7 -> 0.45540424 | H7: =G7 -> 0.45540424
B8: Free Cash Flow to Firm | C8: =C6*(1-C7) -> 2503.5789 | D8: =D6*(1-D7) -> 3093.0336 | E8: =E6*(1-E7) -> 3821.2725 | F8: =F6*(1-F7) -> 4720.9714 | G8: =G6*(1-G7) -> 5832.4997 | H8: =H6*(1-H7) -> 7205.7317
B9: Mid Year Convention | D9: 0.5 | E9: =D9+1 -> 1.5 | F9: =E9+1 -> 2.5 | G9: =F9+1 -> 3.5 | H9: =G9+1 -> 4.5
B10: Discounting Factor | D10: =1/(1+$C$15)^D9 -> 0.92571471 | E10: =1/(1+$C$15)^E9 -> 0.7932891 | F10: =1/(1+$C$15)^F9 -> 0.67980729 | G10: =1/(1+$C$15)^G9 -> 0.5825593 | H10: =1/(1+$C$15)^H9 -> 0.49922286
B11: PV of FCFF | D11: =D8*D10 -> 2863.2667 | E11: =E8*E10 -> 3031.3738 | F11: =F8*F10 -> 3209.3507 | G11: =G8*G10 -> 3397.777 | H11: =H8*H10 -> 3597.266
B13: Expected Growth | C13: ='Intrisic Growth'!K62 -> 0.23544485
B14: Terminal Growth | C14: 0.0538 | D14: long term gdp growth rate
B15: WACC | C15: =WACC!J33 -> 0.16693234
B17: Calculation of Terminal Value | E17: Sensitivity Analysis
E18: =C35 -> 432.42028 | F18: =G18-2% -> 0.1269 | G18: =H18-2% -> 0.1469 | H18: 0.1669 | I18: =H18+2% -> 0.1869 | J18: =I18+2% -> 0.2069
B19: FCFF (n+1) | C19: =H8*(1+C13) -> 8902.2842 | E19: =E20-2% -> 0.0138 | F19: 432.53685 | G19: 371.25133 | H19: 325.97769 | I19: 291.16591 | J19: 263.56526
B20: WACC | C20: =C15 -> 0.16693234 | E20: =E21-2% -> 0.0338 | F20: 520.15343 | G20: 432.53685 | H20: 371.25133 | I20: 325.97769 | J20: 291.16591
B21: Terminal Growth Rate | C21: =C14 -> 0.0538 | E21: 0.0538 | F21: 655.71342 | G21: 520.15343 | H21: 432.53685 | I21: 371.25133 | J21: 325.97769
B22: Terminal Value | C22: =C19/(C20-C21) -> 78689.122 | E22: =E21+2% -> 0.0738 | F22: 893.39016 | G22: 655.71342 | H22: 520.15343 | I22: 432.53685 | J22: 371.25133
E23: =E22+2% -> 0.0938 | F23: 1418.2895 | G23: 893.39016 | H23: 655.71342 | I23: 520.15343 | J23: 432.53685
B24: Calculation of Equity Value per Share
B26: PV of FCFF | C26: =H11 -> 3597.266
B27: PV of Terminal Value | C27: =C22*H10 -> 39283.409
B28: Value of Operating Assets | C28: =SUM(C26:C27) -> 42880.675
B30: Add: Cash | C30: ='Data Sheet'!K69 -> 1073.68
B31: Less: Debt | C31: =SUM('Raw FS'!N7:N8) -> 2293
B32: Value of Equity | C32: =C28+C30-C31 -> 41661.355
B33: No of Shares | C33: ='Data Sheet'!B6 -> 96.344591
B35: Equity Value per Share | C35: =C32/C33 -> 432.42028
B36: current live Share price | C36: 2839
B37: Discount/Premium | C37: =C36/C35 -> 6.565372

Sheet WACC
B2: Weighted Average Cost of Capital
B4: Peer Companies
G5: Debt/ | H5: Debt/ | I5: Levered | J5: Unlevered
B6: Name | C6: Country | D6: Total Debt | E6: Total Equity | F6: Tax Rate | G6: Equity | H6: Capital | I6: Beta | J6: Beta
B7: ='Raw Beta Peers'!C4 -> Asian Paints | C7: India | D7: ='Raw Beta Peers'!F4 -> 3928.93 | E7: ='Raw Beta Peers'!E4 -> 252024.35 | F7: 0.3 | G7: =D7/E7 -> 0.015589486 | H7: =D7/(D7+E7) -> 0.015350184 | I7: ='Raw Beta Peers'!H4 -> 0.867 | J7: =I7/(1+(1-F7)*G7) -> 0.85764087
B8: ='Raw Beta Peers'!C5 -> Berger Paints | C8: India | D8: ='Raw Beta Peers'!F5 -> 635.13 | E8: ='Raw Beta Peers'!E5 -> 60288.18 | F8: 0.3 | G8: =D8/E8 -> 0.010534901 | H8: =D8/(D8+E8) -> 0.010425074 | I8: ='Raw Beta Peers'!H5 -> 0.855 | J8: =I8/(1+(1-F8)*G8) -> 0.84874102
B9: ='Raw Beta Peers'!C6 -> Kansai Nerolac | C9: India | D9: ='Raw Beta Peers'!F6 -> 302.73 | E9: ='Raw Beta Peers'!E6 -> 16329.27 | F9: 0.3 | G9: =D9/E9 -> 0.018539102 | H9: =D9/(D9+E9) -> 0.018201659 | I9: ='Raw Beta Peers'!H6 -> 0.908 | J9: =I9/(1+(1-F9)*G9) -> 0.89636751
B10: ='Raw Beta Peers'!C7 -> JSW Dulux | C10: India | D10: ='Raw Beta Peers'!F7 -> 79.1 | E10: ='Raw Beta Peers'!E7 -> 14276.65 | F10: 0.3 | G10: =D10/E10 -> 0.0055405155 | H10: =D10/(D10+E10) -> 0.0055099873 | I10: ='Raw Beta Peers'!H7 -> 0.449 | J10: =I10/(1+(1-F10)*G10) -> 0.44726534
B11: ='Raw Beta Peers'!C8 -> Indigo Paints | C11: India | D11: ='Raw Beta Peers'!F8 -> 18.37 | E11: ='Raw Beta Peers'!E8 -> 5458.72 | F11: 0.3 | G11: =D11/E11 -> 0.0033652578 | H11: =D11/(D11+E11) -> 0.0033539708 | I11: ='Raw Beta Peers'!H8 -> 1.12 | J11: =I11/(1+(1-F11)*G11) -> 1.1173678
E13: Average | F13: =AVERAGE(F7:F11) -> 0.3 | G13: =AVERAGE(G7:G11) -> 0.010713852 | H13: =AVERAGE(H7:H11) -> 0.010568175 | I13: =AVERAGE(I7:I11) -> 0.8398 | J13: =AVERAGE(J7:J11) -> 0.83347652
E14: Median | F14: =MEDIAN(F7:F11) -> 0.3 | G14: =MEDIAN(G7:G11) -> 0.010534901 | H14: =MEDIAN(H7:H11) -> 0.010425074 | I14: =MEDIAN(I7:I11) -> 0.867 | J14: =MEDIAN(J7:J11) -> 0.85764087
B16: Cost of Debt | G16: Cost of Equity
B17: Pre-tax Cost of Debt | E17: =69/710 -> 0.097183099 | G17: Risk Free Rate | J17: 0.0685
B18: Tax Rate | E18: =F14 -> 0.3 | G18: Equity Risk Premium | J18: =Rm!G7-WACC!J17 -> 0.095992308
B19: After Tax Cost of Debt | E19: =E17*(1-E18) -> 0.068028169 | G19: Levered Beta | J19: =J26 -> 1.0970465
G20: Cost of Equity | J20: =J17+(J18*J19) -> 0.17380803
B22: Capital Structure | G22: Levered Beta
D23: Current | E23: Target | G23: Comps Median Unlevered Beta | J23: =J14 -> 0.85764087
B24: Total Debt | C24: =D7 -> 3928.93 | D24: =C24/$C$26 -> 0.015350184 | E24: 0.065 | G24: Target Debt/ Equity | J24: =E28 -> 0.069518717
B25: Market Capitalization | C25: =E7 -> 252024.35 | D25: =C25/$C$26 -> 0.98464982 | E25: =E26-E24 -> 0.935 | G25: Tax Rate | J25: =E18 -> 0.3
B26: Total Capitalization | C26: =SUM(C24:C25) -> 255953.28 | D26: =C26/$C$26 -> 1 | E26: =D26 -> 1 | G26: Levered Beta | J26: =J23*(1+(1-J24)*J25) -> 1.0970465
B28: Debt / Equity | D28: =D24/D25 -> 0.015589486 | E28: =E24/E25 -> 0.069518717 | G28: Weighted Average Cost of Capital
G29: Cost of Equity | J29: =J20 -> 0.17380803
G30: Equity Weight | J30: =E25 -> 0.935
G31: Cost of Debt | J31: =E19 -> 0.068028169
G32: Debt Weight | J32: =E24 -> 0.065
G33: WACC | J33: =(J29*J30)+(J31*J32) -> 0.16693234

Sheet Rm
B2: Return on Markets
F3: source-primeinvestor
B4: Year | C4: Annual
B5: 2000 | C5: -0.1465 | E5: Average Return | G5: =AVERAGE(C5:C30) -> 0.15149231
B6: 2001 | C6: -0.1618 | E6: Dividend Yield | G6: 0.013
B7: 2002 | C7: 0.0325 | E7: Total Market Returns | G7: =SUM(G5:G6) -> 0.16449231
B8: 2003 | C8: 0.719
B9: 2004 | C9: 0.1068
B10: 2005 | C10: 0.3634
B11: 2006 | C11: 0.3983
B12: 2007 | C12: 0.5477
B13: 2008 | C13: -0.5179
B14: 2009 | C14: 0.7576
B15: 2010 | C15: 0.1795
B16: 2011 | C16: -0.2462
B17: 2012 | C17: 0.277
B18: 2013 | C18: 0.0676
B19: 2014 | C19: 0.3139
... B30: 2025 | C30: 0.1051

Sheet Intrisic Growth
A2: # | B2: Calculation of ROIC | F2: ='Raw FS'!I$2 -> 44256 | G2: ='Raw FS'!J$2 -> 44621 | H2: ='Raw FS'!K$2 -> 44986 | I2: ='Raw FS'!L$2 -> 45352 | J2: ='Raw FS'!M$2 -> 45717 | K2: ='Raw FS'!N$2 -> 46082
B3: Current Assets
B4: ='Raw FS'!B35 -> Inventories | F4: ='Raw FS'!I35 -> 3799 | G4: ='Raw FS'!J35 -> 6153 | H4: ='Raw FS'!K35 -> 6211 | I4: ='Raw FS'!L35 -> 5923 | J4: ='Raw FS'!M35 -> 6719 | K4: ='Raw FS'!N35 -> 5744
B5: ='Raw FS'!B36 -> Trade receivables + | F5: ='Raw FS'!I36 -> 2602 | G5: ='Raw FS'!J36 -> 3871 | H5: ='Raw FS'!K36 -> 4637 | I5: ='Raw FS'!L36 -> 4889 | J5: ='Raw FS'!M36 -> 4314 | K5: ='Raw FS'!N36 -> 4462
B6: ='Raw FS'!B38 -> Loans n Advances | F6: ='Raw FS'!I38 -> 11 | G6: ='Raw FS'!J38 -> 8 | H6: ='Raw FS'!K38 -> 12 | I6: ='Raw FS'!L38 -> 17 | J6: ='Raw FS'!M38 -> 22 | K6: ='Raw FS'!N38 -> 27
B7: ='Raw FS'!B39 -> Other asset items | F7: ='Raw FS'!I39 -> 2555 | G7: ='Raw FS'!J39 -> 2869 | H7: ='Raw FS'!K39 -> 3024 | I7: ='Raw FS'!L39 -> 3555 | J7: ='Raw FS'!M39 -> 3319 | K7: ='Raw FS'!N39 -> 4662
B8: Total Current Assets | F8: =SUM(F4:F7) -> 8967 | G8: =SUM(G4:G7) -> 12901 | H8: =SUM(H4:H7) -> 13884 | I8: =SUM(I4:I7) -> 14384 | J8: =SUM(J4:J7) -> 14374 | K8: =SUM(K4:K7) -> 14895
B10: Current Liabilities
B11: ='Raw FS'!B13 -> Trade Payables | F11: ='Raw FS'!I13 -> 3379 | G11: ='Raw FS'!J13 -> 4164 | H11: ='Raw FS'!K13 -> 3635 | I11: ='Raw FS'!L13 -> 3831 | J11: ='Raw FS'!M13 -> 3848 | K11: ='Raw FS'!N13 -> 3863
B12: ='Raw FS'!B14 -> Advance from Customers | F12: ='Raw FS'!I14 -> 41 | G12: ='Raw FS'!J14 -> 76 | H12: ='Raw FS'!K14 -> 108 | I12: ='Raw FS'!L14 -> 154 | J12: ='Raw FS'!M14 -> 174 | K12: ='Raw FS'!N14 -> 107
B13: ='Raw FS'!B15 -> Other liability items | F13: ='Raw FS'!I15 -> 2613 | G13: ='Raw FS'!J15 -> 2932 | H13: ='Raw FS'!K15 -> 3657 | I13: ='Raw FS'!L15 -> 4017 | J13: ='Raw FS'!M15 -> 3984 | K13: ='Raw FS'!N15 -> 4604
B14: Total Current Liabilities | F14: =SUM(F11:F13) -> 6033 | G14: =SUM(G11:G13) -> 7172 | H14: =SUM(H11:H13) -> 7400 | I14: =SUM(I11:I13) -> 8002 | J14: =SUM(J11:J13) -> 8006 | K14: =SUM(K11:K13) -> 8574
A16: # | B16: Net Working Capital | F16: =F8-F14 -> 2934 | G16: =G8-G14 -> 5729 | H16: =H8-H14 -> 6484 | I16: =I8-I14 -> 6382 | J16: =J8-J14 -> 6368 | K16: =K8-K14 -> 6321
B18: Non Current Assets
B19: ='Raw FS'!B19 -> Land | F19: ='Raw FS'!I19 -> 644 | G19: ='Raw FS'!J19 -> 644 | H19: ='Raw FS'!K19 -> 804 | I19: ='Raw FS'!L19 -> 1126 | J19: ='Raw FS'!M19 -> 1035 | K19: ='Raw FS'!N19 -> 1204
B20: ='Raw FS'!B20 -> Building | F20: ='Raw FS'!I20 -> 2249 | G20: ='Raw FS'!J20 -> 2325 | H20: ='Raw FS'!K20 -> 2883 | I20: ='Raw FS'!L20 -> 3390 | J20: ='Raw FS'!M20 -> 3771 | K20: ='Raw FS'!N20 -> 4124
B21: ='Raw FS'!B21 -> Plant Machinery | F21: ='Raw FS'!I21 -> 4340 | G21: ='Raw FS'!J21 -> 4531 | H21: ='Raw FS'!K21 -> 4825 | I21: ='Raw FS'!L21 -> 5422 | J21: ='Raw FS'!M21 -> 7576 | K21: ='Raw FS'!N21 -> 8210
B22: ='Raw FS'!B22 -> Equipments | F22: ='Raw FS'!I22 -> 243 | G22: ='Raw FS'!J22 -> 253 | H22: ='Raw FS'!K22 -> 270 | I22: ='Raw FS'!L22 -> 298 | J22: ='Raw FS'!M22 -> 325 | K22: ='Raw FS'!N22 -> 351
B23: ='Raw FS'!B23 -> Furniture n fittings | F23: ='Raw FS'!I23 -> 99 | G23: ='Raw FS'!J23 -> 113 | H23: ='Raw FS'!K23 -> 146 | I23: ='Raw FS'!L23 -> 175 | J23: ='Raw FS'!M23 -> 203 | K23: ='Raw FS'!N23 -> 216
B24: ='Raw FS'!B24 -> Vehicles | F24: ='Raw FS'!I24 -> 38 | G24: ='Raw FS'!J24 -> 32 | H24: ='Raw FS'!K24 -> 36 | I24: ='Raw FS'!L24 -> 40 | J24: ='Raw FS'!M24 -> 34 | K24: ='Raw FS'!N24 -> 45
B25: ='Raw FS'!B25 -> Intangible Assets | F25: ='Raw FS'!I25 -> 476 | G25: ='Raw FS'!J25 -> 345 | H25: ='Raw FS'!K25 -> 422 | I25: ='Raw FS'!L25 -> 850 | J25: ='Raw FS'!M25 -> 827 | K25: ='Raw FS'!N25 -> 833
B26: ='Raw FS'!B26 -> Other fixed assets | F26: ='Raw FS'!I26 -> 302 | G26: ='Raw FS'!J26 -> 294 | H26: ='Raw FS'!K26 -> 289 | I26: ='Raw FS'!L26 -> 321 | J26: ='Raw FS'!M26 -> 328 | K26: ='Raw FS'!N26 -> 335
B28: Gross Block | F28: =SUM(F19:F27) -> 8391 | G28: =SUM(G19:G27) -> 8537 | H28: =SUM(H19:H27) -> 9675 | I28: =SUM(I19:I27) -> 11622 | J28: =SUM(J19:J27) -> 14099 | K28: =SUM(K19:K27) -> 15318
B29: Accumulated Depreciation | F29: =-'Raw FS'!I28 -> -2533 | G29: =-'Raw FS'!J28 -> -3019 | H29: =-'Raw FS'!K28 -> -3905 | I29: =-'Raw FS'!L28 -> -4475 | J29: =-'Raw FS'!M28 -> -4879 | K29: =-'Raw FS'!N28 -> -5676
A30: # | B30: Net Non Current Assets | F30: =SUM(F28:F29) -> 5858 | G30: =SUM(G28:G29) -> 5518 | H30: =SUM(H28:H29) -> 5770 | I30: =SUM(I28:I29) -> 7147 | J30: =SUM(J28:J29) -> 9220 | K30: =SUM(K28:K29) -> 9642
A32: # | B32: Invested Capital | F32: =F30+F16 -> 8792 | G32: =G30+G16 -> 11247 | H32: =H30+H16 -> 12254 | I32: =I30+I16 -> 13529 | J32: =J30+J16 -> 15588 | K32: =K30+K16 -> 15963
B33: EBIT | F33: ='Data Sheet'!F34-'Data Sheet'!F26 -> 4328.52 | G33: ='Data Sheet'!G34-'Data Sheet'!G26 -> 4228.89 | H33: ='Data Sheet'!H34-'Data Sheet'!H26 -> 5744.4 | I33: ='Data Sheet'!I34-'Data Sheet'!I26 -> 7455.48 | J33: ='Data Sheet'!J34-'Data Sheet'!J26 -> 5287.61 | K33: ='Data Sheet'!K34-'Data Sheet'!K26 -> 6129.51
A35: # | B35: ROIC | F35: =F33/F32 -> 0.49232484 | G35: =G33/G32 -> 0.3760016 | H35: =H33/H32 -> 0.46877754 | I35: =I33/I32 -> 0.55107399 | J35: =J33/J32 -> 0.33921029 | K35: =K33/K32 -> 0.38398233
A38: # | B38: Calculation of Reinvestment Rate | F38: ='Raw FS'!I$2 -> 44256 | G38: ='Raw FS'!J$2 -> 44621 | H38: ='Raw FS'!K$2 -> 44986 | I38: ='Raw FS'!L$2 -> 45352 | J38: ='Raw FS'!M$2 -> 45717 | K38: ='Raw FS'!N$2 -> 46082
B40: Net Capex | F40: =-SUM('Raw FS'!I54:I55) -> 261 | G40: =-SUM('Raw FS'!J54:J55) -> 511 | H40: =-SUM('Raw FS'!K54:K55) -> 1420 | I40: =-SUM('Raw FS'!L54:L55) -> 2491 | J40: =-SUM('Raw FS'!M54:M55) -> 1820 | K40: =-SUM('Raw FS'!N54:N55) -> 1484
B41: Change in Working Capital | F41: =F16-E16 -> 2934 | G41: =G16-F16 -> 2795 | H41: =H16-G16 -> 755 | I41: =I16-H16 -> -102 | J41: =J16-I16 -> -14 | K41: =K16-J16 -> -47
B43: EBIT | F43: =F33 -> 4328.52 | G43: =G33 -> 4228.89 | H43: =H33 -> 5744.4 | I43: =I33 -> 7455.48 | J43: =J33 -> 5287.61 | K43: =K33 -> 6129.51
B44: Marginal Tax Rate | F44: -0.75 | G44: 0.25 | H44: 0.25 | I44: 0.25 | J44: 0.25 | K44: 0.25
B45: EBIT(1-T) | F45: =F43*(1-F44) -> 7574.91 | G45: =G43*(1-G44) -> 3171.6675 | H45: =H43*(1-H44) -> 4308.3 | I45: =I43*(1-I44) -> 5591.61 | J45: =J43*(1-J44) -> 3965.7075 | K45: =K43*(1-K44) -> 4597.1325
B47: Reinvestment | F47: =SUM(F40:F41) -> 3195 | G47: =SUM(G40:G41) -> 3306 | H47: =SUM(H40:H41) -> 2175 | I47: =SUM(I40:I41) -> 2389 | J47: =SUM(J40:J41) -> 1806 | K47: =SUM(K40:K41) -> 1437
B49: Reinvestment Rate | F49: =F47/F45 -> 0.42178719 | G49: =G47/G45 -> 1.0423539 | H49: =H47/H45 -> 0.5048395 | I49: =I47/I45 -> 0.42724725 | J49: =J47/J45 -> 0.45540424 | K49: =K47/K45 -> 0.31258616
J51: 5 Year Average | K51: =AVERAGE(G49:K49) -> 0.54848621
J52: 5 Year Median | K52: =MEDIAN(G49:K49) -> 0.45540424
A54: # | B54: Calculation of Growth Rate | F54: ='Raw FS'!I$2 -> 44256 | G54: ='Raw FS'!J$2 -> 44621 | H54: ='Raw FS'!K$2 -> 44986 | I54: ='Raw FS'!L$2 -> 45352 | J54: ='Raw FS'!M$2 -> 45717 | K54: ='Raw FS'!N$2 -> 46082
B56: Reinvestment Rate | F56: =F49 -> 0.42178719 | G56: =G49 -> 1.0423539 | H56: =H49 -> 0.5048395 | I56: =I49 -> 0.42724725 | J56: =J49 -> 0.45540424 | K56: =K49 -> 0.31258616
...

Sheet Raw Beta Peers
B2: Raw data for Beta -> screener
B3: S.No. | C3: Name | D3: CMP Rs. | E3: Mar Cap Rs.Cr. | F3: Debt Rs.Cr. | G3: Debt / Eq | H3: Weekly - Two Year Range
B4: 1 | C4: Asian Paints | D4: 2627.45 | E4: 252024.35 | F4: 3928.93 | G4: 0.18 | H4: 0.867
B5: 2 | C5: Berger Paints | D5: 517.05 | E5: 60288.18 | F5: 635.13 | G5: 0.09 | H5: 0.855
B6: 3 | C6: Kansai Nerolac | D6: 201.9 | E6: 16329.27 | F6: 302.73 | G6: 0.05 | H6: 0.908
B7: 4 | C7: JSW Dulux | D7: 3134.95 | E7: 14276.65 | F7: 79.1 | G7: 0.03 | H7: 0.449
B8: 5 | C8: Indigo Paints | D8: 1143.6 | E8: 5458.72 | F8: 18.37 | G8: 0.02 | H8: 1.12

Sheet Raw FS
B2: Bal Sheet Source screener | C2: 42064 | D2: 42430 | E2: 42795 | F2: 43160 | G2: 43525 | H2: 43891 | I2: 44256 | J2: 44621 | K2: 44986 | L2: 45352 | M2: 45717 | N2: 46082
B4: Equity Capital | C4: 96 | D4: 96 | E4: 96 | F4: 96 | G4: 96 | H4: 96 | I4: 96 | J4: 96 | K4: 96 | L4: 96 | M4: 96 | N4: 96
B5: Reserves | C5: 4646 | D5: 6429 | E5: 7508 | F5: 8314 | G5: 9375 | H5: 10034 | I5: 12710 | J5: 13716 | K5: 15896 | L5: 18632 | M5: 19304 | N5: 21276
B6: Borrowings - | C6: 418 | D6: 323 | E6: 560 | F6: 533 | G6: 1320 | H6: 1118 | I6: 1093 | J6: 1587 | K6: 1933 | L6: 2474 | M6: 2290 | N6: 3929
B7: Long term Borrowings | C7: 78 | D7: 73 | E7: 41 | F7: 28 | G7: 19 | H7: 19 | I7: 15 | J7: 45 | K7: 76 | L7: 54 | M7: 260 | N7: 1247
B8: Short term Borrowings | C8: 332 | D8: 231 | E8: 504 | F8: 492 | G8: 597 | H8: 321 | I8: 334 | J8: 731 | K8: 896 | L8: 1053 | M8: 604 | N8: 1046
B9: Lease Liabilities | C9: 0 | D9: 0 | E9: 0 | F9: 0 | G9: 693 | H9: 764 | I9: 745 | J9: 811 | K9: 960 | L9: 1367 | M9: 1427 | N9: 1636
B10: Other Borrowings | C10: 8 | D10: 20 | E10: 15 | F10: 13 | G10: 11 | H10: 15 | I10: 0 | J10: 0 | K10: 0 | L10: 0 | M10: 0 | N10: 0
B11: Other Liabilities - | C11: 3754 | D11: 3711 | E11: 4241 | F11: 4820 | G11: 5459 | H11: 4889 | I11: 6456 | J11: 7560 | K11: 7854 | L11: 8698 | M11: 8665 | N11: 9218
B12: Non controlling int | C12: 264 | D12: 384 | E12: 375 | F12: 328 | G12: 361 | H12: 404 | I12: 423 | J12: 388 | K12: 454 | L12: 695 | M12: 659 | N12: 643
B13: Trade Payables | C13: 1549 | D13: 1565 | E13: 1923 | F13: 2160 | G13: 2394 | H13: 2137 | I13: 3379 | J13: 4164 | K13: 3635 | L13: 3831 | M13: 3848 | N13: 3863
B14: Advance from Customers | C14: 5 | D14: 12 | E14: 17 | F14: 16 | G14: 13 | H14: 29 | I14: 41 | J14: 76 | K14: 108 | L14: 154 | M14: 174 | N14: 107
... B72: CFO/OP | C72: 0.81 | D72: 1.12 | E72: 0.82 | F72: 1 | G72: 0.92 | H72: 0.97 | I72: 0.98 | J72: 0.45 | K72: 0.91 | L72: 1.05 | M72: 0.97 | N72: 1.29

Sheet Data Sheet
A1: COMPANY NAME | B1: ASIAN PAINTS LTD | E1: =IF(B2<>B3, "A NEW VERSION OF THE WORKSHEET IS AVAILABLE", "")
A2: LATEST VERSION | B2: 2.1 | E2: PLEASE DO NOT MAKE ANY CHANGES TO THIS SHEET
A3: CURRENT VERSION | B3: 2.1
A5: META
A6: Number of shares | B6: =IF(B9>0, B9/B8, 0) -> 96.344591
A7: Face Value | B7: 1
A8: Current Price | B8: 2625.2
A9: Market Capitalization | B9: 252923.82
A15: PROFIT & LOSS | B15: =B26+B34 -> 3589.63 | K15: =K17-K18-K20-K21-K22-K23-K19 -> 9189.2
A16: Report Date | B16: 42825 | C16: 43190 | D16: 43555 | E16: 43921 | F16: 44286 | G16: 44651 | H16: 45016 | I16: 45382 | J16: 45747 | K16: 46112
A17: Sales | B17: 15061.99 | C17: 16824.55 | D17: 19240.13 | E17: 20211.25 | F17: 21712.79 | G17: 29101.28 | H17: 34488.59 | I17: 35494.73 | J17: 33905.62 | K17: 35583.54
A18: Raw Material Cost | B18: 7452.6 | C18: 8128.17 | D18: 9974.4 | E18: 9981.99 | F18: 10425.55 | G18: 17123.25 | H18: 18985.53 | I18: 17410.84 | J18: 17504.51 | K18: 17142.01
A19: Change in Inventory | B19: 528.6 | C19: -142.13 | D19: 293.26 | E19: 239.15 | F19: 92.45 | G19: 1324.97 | H19: 309.73 | I19: -363.8 | J19: 205 | K19: -603.68
A20: Power and Fuel | B20: 106.02 | C20: 110.3 | D20: 119.63 | E20: 97.79 | F20: 86.05 | G20: 117.23 | H20: 138.29 | I20: 133.25 | J20: 148.58 | K20: 167.1
A21: Other Mfr. Exp | B21: 1662.75 | C21: 1691.68 | D21: 1862.35 | E21: 1946.12 | F21: 2068.31 | G21: 2880.45 | H21: 2916.2 | I21: 2767.18 | J21: 2687.4 | K21: 2767.11
A22: Employee Cost | B22: 1039.89 | C22: 1121.89 | D22: 1242.69 | E22: 1371.27 | F22: 1547.61 | G22: 1794.61 | H22: 2036.41 | I22: 2334.92 | J22: 2605.78 | K22: 2809.73
A23: Selling and admin | B23: 4364.04 | C23: 2254.92 | D23: 2366.87 | E23: 2311.51 | F23: 2245.69 | G23: 2941.98 | H23: 3500.84 | I23: 3811.86 | J23: 3874.94 | K23: 4112.07
A24: Other Expenses | B24: -2028.47 | C24: 171.45 | D24: 202.51 | E24: 579.95 | F24: 576.43 | G24: 765.12 | H24: 961.21 | I24: 1087.9 | J24: 1283.2 | K24: 1282.11
A25: Other Income | B25: 337.9 | C25: 336.41 | D25: 273.77 | E25: 350.1 | F25: 331.65 | G25: 295.88 | H25: 431.46 | I25: 820.96 | J25: 350.22 | K25: 727.97
A26: Depreciation | B26: 334.79 | C26: 360.47 | D26: 622.14 | E26: 780.5 | F26: 791.27 | G26: 816.36 | H26: 858.02 | I26: 853 | J26: 1026.34 | K26: 1228.85
A27: Interest | B27: 37.33 | C27: 41.47 | D27: 110.47 | E27: 102.33 | F27: 91.63 | G27: 95.41 | H27: 144.45 | I27: 205.17 | J27: 227.02 | K27: 195.41
... A31: Dividend Amount | B31: 987.98 | C31: 834.5 | D31: 1007.16 | E31: 1151.04 | F31: 1712.17 | G31: 1836.87 | H31: 2460.35 | I31: 3194.14 | J31: 2378.82 | K31: 2637.8
A32: Effective Tax Rate | B32: =B29/B28 -> 0.31872859 | C32: =C29/C28 -> 0.33167648 | D32: =D29/D28 -> 0.33213151 | E32: =E29/E28 -> 0.23555816 | F32: =F29/F28 -> 0.25499785 | G32: =G29/G28 -> 0.26336766 | H32: =H29/H28 -> 0.26253201 | I32: =I29/I28 -> 0.24362221 | ... K32: =K29/K28 -> 0.26797136
A34: EBITDA | B34: =+B30+B29+B27+B26 -> 3254.84 | C34: =+C30+C29+C27+C26 -> 3481.83 | D34: =+D30+D29+D27+D26 -> 3986.59 | E34: =+E30+E29+E27+E26 -> 4442.85 | F34: =+F30+F29+F27+F26 -> 5119.79 | G34: =+G30+G29+G27+G26 -> 5045.25 | H34: =+H30+H29+H27+H26 -> 6602.42 | I34: =+I30+I29+I27+I26 -> 8308.48 | ... K34: =+K30+K29+K27+K26 -> 7358.36
A40: Quarters
A41: Report Date | B41: 45382 | C41: 45473 | D41: 45565 | E41: 45657 | F41: 45747 | G41: 45838 | H41: 45930 | I41: 46022 | J41: 46112 | K41: 46203
A42: Sales | B42: 8730.76 | C42: 8969.73 | D42: 8027.54 | E42: 8549.44 | F42: 8358.91 | G42: 8938.55 | H42: 8531.27 | I42: 8867.02 | J42: 9246.7 | K42: 10541.94
A43: Expenses | B43: 7039.39 | C43: 7275.96 | D43: 6788.03 | E43: 6912.71 | F43: 6922.71 | G43: 7313.58 | H43: 7027.89 | I43: 7086.06 | J43: 7460.09 | K43: 8373.18
A44: Other Income | B44: 212.43 | C44: 192.93 | D44: 24.53 | E44: 192.82 | F44: -60.06 | G44: 229.11 | H44: 236.94 | I44: 69.14 | J44: 196.59 | K44: 279.01
A45: Depreciation | B45: 225.61 | C45: 227.7 | D45: 241.99 | E45: 255.55 | F45: 301.1 | G45: 300.87 | H45: 304.93 | I45: 313.07 | J45: 309.98 | K45: 304.19
A46: Interest | B46: 54.1 | C46: 55.38 | D46: 63.01 | E46: 55.84 | F46: 52.79 | G46: 44.5 | H46: 43.87 | I46: 47.94 | J46: 59.1 | K46: 47.83
A47: Profit before tax | B47: 1624.09 | C47: 1603.62 | D47: 959.04 | E47: 1518.16 | F47: 1022.25 | G47: 1508.71 | H47: 1391.52 | I47: 1489.09 | J47: 1614.12 | K47: 2095.75
A48: Tax | B48: 348.79 | C48: 416.83 | D48: 265.38 | E48: 389.73 | F48: 321.42 | G48: 391.66 | H48: 373.29 | I48: 415.17 | J48: 428.63 | K48: 536.3
A49: Net profit | B49: 1256.72 | C49: 1169.98 | D49: 694.64 | E49: 1110.48 | F49: 692.13 | G49: 1099.77 | H49: 993.59 | I49: 1059.87 | J49: 1172.12 | K49: 1539.25
A50: Operating Profit | B50: 1691.37 | C50: 1693.77 | D50: 1239.51 | E50: 1636.73 | F50: 1436.2 | G50: 1624.97 | H50: 1503.38 | I50: 1780.96 | J50: 1786.61 | K50: 2168.76
A51: EBITDA | B51: =B49+B48+B46+B45 -> 1885.22 | C51: =C49+C48+C46+C45 -> 1869.89 | D51: =D49+D48+D46+D45 -> 1265.02 | E51: =E49+E48+E46+E45 -> 1811.6 | F51: =F49+F48+F46+F45 -> 1367.44 | G51: =G49+G48+G46+G45 -> 1836.8 | H51: =H49+H48+H46+H45 -> 1715.68 | I51: =I49+I48+I46+I45 -> 1836.05 | ... K51: =K49+K48+K46+K45 -> 2427.57
A55: BALANCE SHEET
A56: Report Date | B56: 42825 | C56: 43190 | D56: 43555 | E56: 43921 | F56: 44286 | G56: 44651 | H56: 45016 | I56: 45382 | J56: 45747 | K56: 46112
A57: Equity Share Capital | B57: 95.92 | C57: 95.92 | D57: 95.92 | E57: 95.92 | F57: 95.92 | G57: 95.92 | H57: 95.92 | I57: 95.92 | J57: 95.92 | K57: 95.92
A58: Reserves | B58: 7507.97 | C58: 8314.31 | D58: 9374.63 | E58: 10034.24 | F58: 12710.37 | G58: 13715.64 | H58: 15896.31 | I58: 18632.38 | J58: 19303.89 | K58: 21275.67
...
